Workbook

Sheet 00_Indice
B2: Nexum Financial Advisors — Modelo de inversión Familia Allende Cunich (v2)
B3: Grupo 11 · ESF 2026-2 · Datos al 31-ago-2026 · Generado 11-10-2026 con codigo/run_all.py + excel_modelo.py
B5: Flujo del modelo
B6: Hoja | C6: Contenido
B7: 01_Supuestos | C7: Datos del cliente, objetivos, tipos de cambio, reglas de las estrategias y supuestos de mercado (todas las entradas)
B8: 02_Objetivos_TIR | C8: Flujos años 0-50, TIR real requerida (fórmula IRR) y factibilidad
B9: 03_Estrategias | C9: Reglas, resultados del backtest y comparación con su benchmark de cada estrategia activa
B10: 04_Datos_Mensuales | C10: Retornos mensuales 2013-2026 de los 6 activos y del benchmark (salida de los backtests point-in-time)
B11: 05_Markowitz | C11: Medias, volatilidades y covarianzas con fórmulas; cartera de máximo Sharpe histórico
B12: 06_Black_Litterman | C12: Prior de paridad de riesgo, π implícito, vistas y μ posterior calculados con fórmulas matriciales
B13: 07_Benchmark_Metricas | C13: Benchmark de política por sleeve, métricas de desempeño, tracking error ex-ante e IR
B14: 08_Montecarlo | C14: Probabilidad de cumplir cada objetivo: USD y UF, histórico y prospectivo, Nexum vs AGF; palancas
B15: 09_Validacion | C15: Impacto de correcciones, robustez de parámetros, walk-forward fuera de muestra y sesgos declarados
B16: 10_Bitacora_Auditoria | C16: Errores encontrados en el modelo original y cómo se corrigieron
B19: Convención de colores
B20: Azul: dato de entrada editable
B21: Negro: fórmula
B22: Verde: vínculo a otra hoja
B23: Gris itálica: resultado calculado en Python (codigo/), reproducible con run_all.py
B25: Resultado principal
B26: TIR real requerida (enunciado) | C26: ='02_Objetivos_TIR'!D8
B27: P(3 objetivos) histórico, USD | C27: 0.95955
B28: P(3 objetivos) prospectivo, USD | C28: 0.4653
B29: P(Educación) en todos los escenarios | C29: 0.999

Sheet 01_Supuestos
B2: Supuestos y datos de entrada
B3: Fuente: enunciado 'Planificación Actividad de Graduación' y BCCh (11-ago-2026). Todo número del modelo nace aquí o en codigo/config.py.
B5: Parámetro | D5: Valor | E5: Fuente / nota
B6: Cliente y mercado
B7: Capital inicial (USD) | D7: 150000 | E7: Enunciado
B8: Reserva operativa + cambiaria | D8: 0.04 | E8: 2% caja + 2% reserva; no se invierte
B9: Aporte anual (USD, abril) | D9: 10000 | E9: Enunciado: hasta que Tomás cumpla 65
B10: N° de aportes | D10: 19 | E10: 46 → 65 años
B11: USD/CLP | D11: 911.77 | E11: BCCh 11-ago-2026
B12: UF/CLP | D12: 40846 | E12: BCCh 11-ago-2026
B13: USD por UF | D13: =D12/D11 | E13: Fórmula
B14: Inflación EE.UU. (deflactor) | D14: 0.02 | E14: Supuesto
B15: Objetivos
B16: Arancel por hijo (CLP de hoy) | D16: 65000000 | E16: Enunciado
B17: Años de carrera | D17: 5 | E17: Supuesto: 5 pagos anuales
B18: Pago anual por hijo (USD) | D18: =D16/D11/D17 | E18: Fórmula
B19: Inicio Vicente (año) | D19: 14 | E19: Enunciado ~14
B20: Inicio Emilia (año) | D20: 16 | E20: Enunciado ~16
B21: Villarrica: desembolso (UF) | D21: 10500 | E21: Enunciado; UF 15.000 restantes vienen de la venta de la casa (fuera de la cartera)
B22: Año Villarrica | D22: 25 | E22: Francisca cumple 65
B23: Herencia (USD de hoy) | D23: 500000 | E23: USD 250 mil por hijo
B24: Año herencia | D24: 50 | E24: Francisca cumple 90
B25: Tasa real libre de riesgo | D25: 0.025 | E25: Bono 10a EE.UU. ~5,2% − inflación implícita ~2,5%
B26: Asignación y gestión activa
B27: Núcleo pasivo mínimo | D27: 0.6 | E27: Política
B28: Núcleo pasivo máximo | D28: 0.7 | E28: Política
B29: δ aversión al riesgo (BL) | D29: 2.5 | E29: Black y Litterman (1992); ver A implícito en 06
B30: τ incertidumbre del prior (BL) | D30: 0.05 | E30: He y Litterman (1999)
B31: Alfa objetivo anual | D31: 0.015 | E31: Presupuesto de riesgo activo
B32: Information ratio objetivo | D32: 0.5 | E32: Grinold y Kahn: 0,5 = bueno
B33: TE objetivo = alfa / IR | D33: =D31/D32 | E33: Fórmula
B34: TE máximo | D34: 0.04 | E34: Alfa 2% con IR 0,5
B35: Costo de transacción por lado | D35: 0.001 | E35: Sobre el monto transado
B37: Reglas de las estrategias activas
B38: Estrategia | C38: Elemento | D38: Regla
B39: Momentum en acciones | C39: Universo | D39: S&P 500 point-in-time
C40: Filtros | D40: r3m > 0%, r6m > 5%, r12m > 10%, precio > media 200d, liquidez ≥ USD 5M/día, Sharpe 12m ≥ 0,5 (vol. 12 meses)
C41: Ranking | D41: 50% percentil r6m + 50% percentil r12m
C42: Cartera | D42: Top 10, peso igual, máx. 25% por sector GICS; mensual
B43: Low-Volatility | C43: Universo | D43: S&P 500 point-in-time; precio ≥ USD 5; liquidez ≥ USD 5M/día
...

Sheet 02_Objetivos_TIR
B2: Objetivos, flujos y TIR real requerida
B3: USD reales de hoy. Entradas positivas, desembolsos negativos. Fórmulas vinculadas a 01_Supuestos.
B5: Indicador | D5: Valor | M5: Escenarios de TIR (Python, objetivos.py)
B6: VP recursos a tasa libre de riesgo | D6: =NPV('01_Supuestos'!$D$25,E14:E63)+E13 | M6: Escenario | N6: TIR real requerida
B7: VP objetivos a tasa libre de riesgo | D7: =-(NPV('01_Supuestos'!$D$25,J14:J63)+J13) | M7: Base: flujos del enunciado (19 aportes reales) | N7: 0.046531305
B8: TIR real requerida (IRR de los flujos netos) | D8: =IRR(K13:K63,0.04) | M8: 14 aportes efectivos (riesgo de empleo) | N8: 0.050341092
B9: Cobertura (recursos / objetivos) | D9: =D6/D7 | M9: Aportes en USD nominales (inflación 2,5%) | N9: 0.050401986
M10: Arancel crece 2% real anual | N10: 0.050851086
M11: Aportes nominales + arancel +2% real | N11: 0.054830355
B12: Año | C12: Capital | D12: Aporte | E12: Entradas | F12: Educ. Vicente | G12: Educ. Emilia | H12: Villarrica | I12: Herencia | J12: Salidas | K12: Flujo neto | M12: Lo anterior con 14 aportes | N12: 0.057409072
B13: 0 | C13: =IF(B13=0,'01_Supuestos'!$D$7*(1-'01_Supuestos'!$D$8),0) | D13: =IF(AND(B13>=1,B13<='01_Supuestos'!$D$10),'01_Supuestos'!$D$9,0) | E13: =C13+D13 | F13: =IF(AND(B13>='01_Supuestos'!$D$19,B13<'01_Supuestos'!$D$19+'01_Supuestos'!$D$17),-'01_Supuestos'!$D$18,0) | G13: =IF(AND(B13>='01_Supuestos'!$D$20,B13<'01_Supuestos'!$D$20+'01_Supuestos'!$D$17),-'01_Supuestos'!$D$18,0) | H13: =IF(B13='01_Supuestos'!$D$22,-'01_Supuestos'!$D$21*'01_Supuestos'!$D$13,0) | I13: =IF(B13='01_Supuestos'!$D$24,-'01_Supuestos'!$D$23,0) | J13: =SUM(F13:I13) | K13: =E13+J13 | M13: Palanca: herencia USD 250 mil | N13: 0.041650245
B14: 1 | C14: =IF(B14=0,'01_Supuestos'!$D$7*(1-'01_Supuestos'!$D$8),0) | D14: =IF(AND(B14>=1,B14<='01_Supuestos'!$D$10),'01_Supuestos'!$D$9,0) | E14: =C14+D14 | F14: =IF(AND(B14>='01_Supuestos'!$D$19,B14<'01_Supuestos'!$D$19+'01_Supuestos'!$D$17),-'01_Supuestos'!$D$18,0) | G14: =IF(AND(B14>='01_Supuestos'!$D$20,B14<'01_Supuestos'!$D$20+'01_Supuestos'!$D$17),-'01_Supuestos'!$D$18,0) | H14: =IF(B14='01_Supuestos'!$D$22,-'01_Supuestos'!$D$21*'01_Supuestos'!$D$13,0) | I14: =IF(B14='01_Supuestos'!$D$24,-'01_Supuestos'!$D$23,0) | J14: =SUM(F14:I14) | K14: =E14+J14 | M14: Palanca: Villarrica -25% | N14: 0.040108617
B15: 2 | C15: =IF(B15=0,'01_Supuestos'!$D$7*(1-'01_Supuestos'!$D$8),0) | D15: =IF(AND(B15>=1,B15<='01_Supuestos'!$D$10),'01_Supuestos'!$D$9,0) | E15: =C15+D15 | F15: =IF(AND(B15>='01_Supuestos'!$D$19,B15<'01_Supuestos'!$D$19+'01_Supuestos'!$D$17),-'01_Supuestos'!$D$18,0) | G15: =IF(AND(B15>='01_Supuestos'!$D$20,B15<'01_Supuestos'!$D$20+'01_Supuestos'!$D$17),-'01_Supuestos'!$D$18,0) | H15: =IF(B15='01_Supuestos'!$D$22,-'01_Supuestos'!$D$21*'01_Supuestos'!$D$13,0) | I15: =IF(B15='01_Supuestos'!$D$24,-'01_Supuestos'!$D$23,0) | J15: =SUM(F15:I15) | K15: =E15+J15 | M15: Palanca: ambas | N15: 0.033757247
B16: 3 | C16: =IF(B16=0,'01_Supuestos'!$D$7*(1-'01_Supuestos'!$D$8),0) | D16: =IF(AND(B16>=1,B16<='01_Supuestos'!$D$10),'01_Supuestos'!$D$9,0) | E16: =C16+D16 | F16: =IF(AND(B16>='01_Supuestos'!$D$19,B16<'01_Supuestos'!$D$19+'01_Supuestos'!$D$17),-'01_Supuestos'!$D$18,0) | G16: =IF(AND(B16>='01_Supuestos'!$D$20,B16<'01_Supuestos'!$D$20+'01_Supuestos'!$D$17),-'01_Supuestos'!$D$18,0) | H16: =IF(B16='01_Supuestos'!$D$22,-'01_Supuestos'!$D$21*'01_Supuestos'!$D$13,0) | I16: =IF(B16='01_Supuestos'!$D$24,-'01_Supuestos'!$D$23,0) | J16: =SUM(F16:I16) | K16: =E16+J16
B17: 4 | C17: =IF(B17=0,'01_Supuestos'!$D$7*(1-'01_Supuestos'!$D$8),0) | D17: =IF(AND(B17>=1,B17<='01_Supuestos'!$D$10),'01_Supuestos'!$D$9,0) | E17: =C17+D17 | F17: =IF(AND(B17>='01_Supuestos'!$D$19,B17<'01_Supuestos'!$D$19+'01_Supuestos'!$D$17),-'01_Supuestos'!$D$18,0) | G17: =IF(AND(B17>='01_Supuestos'!$D$20,B17<'01_Supuestos'!$D$20+'01_Supuestos'!$D$17),-'01_Supuestos'!$D$18,0) | H17: =IF(B17='01_Supuestos'!$D$22,-'01_Supuestos'!$D$21*'01_Supuestos'!$D$13,0) | I17: =IF(B17='01_Supuestos'!$D$24,-'01_Supuestos'!$D$23,0) | J17: =SUM(F17:I17) | K17: =E17+J17
B18: 5 | C18: =IF(B18=0,'01_Supuestos'!$D$7*(1-'01_Supuestos'!$D$8),0) | D18: =IF(AND(B18>=1,B18<='01_Supuestos'!$D$10),'01_Supuestos'!$D$9,0) | E18: =C18+D18 | F18: =IF(AND(B18>='01_Supuestos'!$D$19,B18<'01_Supuestos'!$D$19+'01_Supuestos'!$D$17),-'01_Supuestos'!$D$18,0) | G18: =IF(AND(B18>='01_Supuestos'!$D$20,B18<'01_Supuestos'!$D$20+'01_Supuestos'!$D$17),-'01_Supuestos'!$D$18,0) | H18: =IF(B18='01_Supuestos'!$D$22,-'01_Supuestos'!$D$21*'01_Supuestos'!$D$13,0) | I18: =IF(B18='01_Supuestos'!$D$24,-'01_Supuestos'!$D$23,0) | J18: =SUM(F18:I18) | K18: =E18+J18 | M18: Plan de desembolsos
B19: 6 | C19: =IF(B19=0,'01_Supuestos'!$D$7*(1-'01_Supuestos'!$D$8),0) | D19: =IF(AND(B19>=1,B19<='01_Supuestos'!$D$10),'01_Supuestos'!$D$9,0) | E19: =C19+D19 | F19: =IF(AND(B19>='01_Supuestos'!$D$19,B19<'01_Supuestos'!$D$19+'01_Supuestos'!$D$17),-'01_Supuestos'!$D$18,0) | G19: =IF(AND(B19>='01_Supuestos'!$D$20,B19<'01_Supuestos'!$D$20+'01_Supuestos'!$D$17),-'01_Supuestos'!$D$18,0) | H19: =IF(B19='01_Supuestos'!$D$22,-'01_Supuestos'!$D$21*'01_Supuestos'!$D$13,0) | I19: =IF(B19='01_Supuestos'!$D$24,-'01_Supuestos'!$D$23,0) | J19: =SUM(F19:I19) | K19: =E19+J19 | M19: Año | N19: Concepto | O19: USD reales | P19: UF | Q19: CLP de hoy
B20: 7 | C20: =IF(B20=0,'01_Supuestos'!$D$7*(1-'01_Supuestos'!$D$8),0) | D20: =IF(AND(B20>=1,B20<='01_Supuestos'!$D$10),'01_Supuestos'!$D$9,0) | E20: =C20+D20 | F20: =IF(AND(B20>='01_Supuestos'!$D$19,B20<'01_Supuestos'!$D$19+'01_Supuestos'!$D$17),-'01_Supuestos'!$D$18,0) | G20: =IF(AND(B20>='01_Supuestos'!$D$20,B20<'01_Supuestos'!$D$20+'01_Supuestos'!$D$17),-'01_Supuestos'!$D$18,0) | H20: =IF(B20='01_Supuestos'!$D$22,-'01_Supuestos'!$D$21*'01_Supuestos'!$D$13,0) | I20: =IF(B20='01_Supuestos'!$D$24,-'01_Supuestos'!$D$23,0) | J20: =SUM(F20:I20) | K20: =E20+J20 | M20: 14 | N20: Educación | O20: 14257.982 | P20: 318.26862 | Q20: 13000000
B21: 8 | C21: =IF(B21=0,'01_Supuestos'!$D$7*(1-'01_Supuestos'!$D$8),0) | D21: =IF(AND(B21>=1,B21<='01_Supuestos'!$D$10),'01_Supuestos'!$D$9,0) | E21: =C21+D21 | F21: =IF(AND(B21>='01_Supuestos'!$D$19,B21<'01_Supuestos'!$D$19+'01_Supuestos'!$D$17),-'01_Supuestos'!$D$18,0) | G21: =IF(AND(B21>='01_Supuestos'!$D$20,B21<'01_Supuestos'!$D$20+'01_Supuestos'!$D$17),-'01_Supuestos'!$D$18,0) | H21: =IF(B21='01_Supuestos'!$D$22,-'01_Supuestos'!$D$21*'01_Supuestos'!$D$13,0) | I21: =IF(B21='01_Supuestos'!$D$24,-'01_Supuestos'!$D$23,0) | J21: =SUM(F21:I21) | K21: =E21+J21 | M21: 15 | N21: Educación | O21: 14257.982 | P21: 318.26862 | Q21: 13000000
B22: 9 | C22: =IF(B22=0,'01_Supuestos'!$D$7*(1-'01_Supuestos'!$D$8),0) | D22: =IF(AND(B22>=1,B22<='01_Supuestos'!$D$10),'01_Supuestos'!$D$9,0) | E22: =C22+D22 | F22: =IF(AND(B22>='01_Supuestos'!$D$19,B22<'01_Supuestos'!$D$19+'01_Supuestos'!$D$17),-'01_Supuestos'!$D$18,0) | G22: =IF(AND(B22>='01_Supuestos'!$D$20,B22<'01_Supuestos'!$D$20+'01_Supuestos'!$D$17),-'01_Supuestos'!$D$18,0) | H22: =IF(B22='01_Supuestos'!$D$22,-'01_Supuestos'!$D$21*'01_Supuestos'!$D$13,0) | I22: =IF(B22='01_Supuestos'!$D$24,-'01_Supuestos'!$D$23,0) | J22: =SUM(F22:I22) | K22: =E22+J22 | M22: 16 | N22: Educación | O22: 28515.963 | P22: 636.53724 | Q22: 26000000
B23: 10 | C23: =IF(B23=0,'01_Supuestos'!$D$7*(1-'01_Supuestos'!$D$8),0) | D23: =IF(AND(B23>=1,B23<='01_Supuestos'!$D$10),'01_Supuestos'!$D$9,0) | E23: =C23+D23 | F23: =IF(AND(B23>='01_Supuestos'!$D$19,B23<'01_Supuestos'!$D$19+'01_Supuestos'!$D$17),-'01_Supuestos'!$D$18,0) | G23: =IF(AND(B23>='01_Supuestos'!$D$20,B23<'01_Supuestos'!$D$20+'01_Supuestos'!$D$17),-'01_Supuestos'!$D$18,0) | H23: =IF(B23='01_Supuestos'!$D$22,-'01_Supuestos'!$D$21*'01_Supuestos'!$D$13,0) | I23: =IF(B23='01_Supuestos'!$D$24,-'01_Supuestos'!$D$23,0) | J23: =SUM(F23:I23) | K23: =E23+J23 | M23: 17 | N23: Educación | O23: 28515.963 | P23: 636.53724 | Q23: 26000000
B24: 11 | C24: =IF(B24=0,'01_Supuestos'!$D$7*(1-'01_Supuestos'!$D$8),0) | D24: =IF(AND(B24>=1,B24<='01_Supuestos'!$D$10),'01_Supuestos'!$D$9,0) | E24: =C24+D24 | F24: =IF(AND(B24>='01_Supuestos'!$D$19,B24<'01_Supuestos'!$D$19+'01_Supuestos'!$D$17),-'01_Supuestos'!$D$18,0) | G24: =IF(AND(B24>='01_Supuestos'!$D$20,B24<'01_Supuestos'!$D$20+'01_Supuestos'!$D$17),-'01_Supuestos'!$D$18,0) | H24: =IF(B24='01_Supuestos'!$D$22,-'01_Supuestos'!$D$21*'01_Supuestos'!$D$13,0) | I24: =IF(B24='01_Supuestos'!$D$24,-'01_Supuestos'!$D$23,0) | J24: =SUM(F24:I24) | K24: =E24+J24 | M24: 18 | N24: Educación | O24: 28515.963 | P24: 636.53724 | Q24: 26000000
B25: 12 | C25: =IF(B25=0,'01_Supuestos'!$D$7*(1-'01_Supuestos'!$D$8),0) | D25: =IF(AND(B25>=1,B25<='01_Supuestos'!$D$10),'01_Supuestos'!$D$9,0) | E25: =C25+D25 | F25: =IF(AND(B25>='01_Supuestos'!$D$19,B25<'01_Supuestos'!$D$19+'01_Supuestos'!$D$17),-'01_Supuestos'!$D$18,0) | G25: =IF(AND(B25>='01_Supuestos'!$D$20,B25<'01_Supuestos'!$D$20+'01_Supuestos'!$D$17),-'01_Supuestos'!$D$18,0) | H25: =IF(B25='01_Supuestos'!$D$22,-'01_Supuestos'!$D$21*'01_Supuestos'!$D$13,0) | I25: =IF(B25='01_Supuestos'!$D$24,-'01_Supuestos'!$D$23,0) | J25: =SUM(F25:I25) | K25: =E25+J25 | M25: 19 | N25: Educación | O25: 14257.982 | P25: 318.26862 | Q25: 13000000
B26: 13 | C26: =IF(B26=0,'01_Supuestos'!$D$7*(1-'01_Supuestos'!$D$8),0) | D26: =IF(AND(B26>=1,B26<='01_Supuestos'!$D$10),'01_Supuestos'!$D$9,0) | E26: =C26+D26 | F26: =IF(AND(B26>='01_Supuestos'!$D$19,B26<'01_Supuestos'!$D$19+'01_Supuestos'!$D$17),-'01_Supuestos'!$D$18,0) | G26: =IF(AND(B26>='01_Supuestos'!$D$20,B26<'01_Supuestos'!$D$20+'01_Supuestos'!$D$17),-'01_Supuestos'!$D$18,0) | H26: =IF(B26='01_Supuestos'!$D$22,-'01_Supuestos'!$D$21*'01_Supuestos'!$D$13,0) | I26: =IF(B26='01_Supuestos'!$D$24,-'01_Supuestos'!$D$23,0) | J26: =SUM(F26:I26) | K26: =E26+J26 | M26: 20 | N26: Educación | O26: 14257.982 | P26: 318.26862 | Q26: 13000000
B27: 14 | C27: =IF(B27=0,'01_Supuestos'!$D$7*(1-'01_Supuestos'!$D$8),0) | D27: =IF(AND(B27>=1,B27<='01_Supuestos'!$D$10),'01_Supuestos'!$D$9,0) | E27: =C27+D27 | F27: =IF(AND(B27>='01_Supuestos'!$D$19,B27<'01_Supuestos'!$D$19+'01_Supuestos'!$D$17),-'01_Supuestos'!$D$18,0) | G27: =IF(AND(B27>='01_Supuestos'!$D$20,B27<'01_Supuestos'!$D$20+'01_Supuestos'!$D$17),-'01_Supuestos'!$D$18,0) | H27: =IF(B27='01_Supuestos'!$D$22,-'01_Supuestos'!$D$21*'01_Supuestos'!$D$13,0) | I27: =IF(B27='01_Supuestos'!$D$24,-'01_Supuestos'!$D$23,0) | J27: =SUM(F27:I27) | K27: =E27+J27 | M27: 25 | N27: Villarrica (desembolso; UF 15.000 adicionales vienen de la venta de la casa, fuera de la cartera) | O27: 470385.08 | P27: 10500 | Q27: 428883000
B28: 15 | C28: =IF(B28=0,'01_Supuestos'!$D$7*(1-'01_Supuestos'!$D$8),0) | D28: =IF(AND(B28>=1,B28<='01_Supuestos'!$D$10),'01_Supuestos'!$D$9,0) | E28: =C28+D28 | F28: =IF(AND(B28>='01_Supuestos'!$D$19,B28<'01_Supuestos'!$D$19+'01_Supuestos'!$D$17),-'01_Supuestos'!$D$18,0) | G28: =IF(AND(B28>='01_Supuestos'!$D$20,B28<'01_Supuestos'!$D$20+'01_Supuestos'!$D$17),-'01_Supuestos'!$D$18,0) | H28: =IF(B28='01_Supuestos'!$D$22,-'01_Supuestos'!$D$21*'01_Supuestos'!$D$13,0) | I28: =IF(B28='01_Supuestos'!$D$24,-'01_Supuestos'!$D$23,0) | J28: =SUM(F28:I28) | K28: =E28+J28 | M28: 50 | N28: Herencia (USD 250 mil por hijo) | O28: 500000 | P28: 11161.068 | Q28: 455885000
B29: 16 | C29: =IF(B29=0,'01_Supuestos'!$D$7*(1-'01_Supuestos'!$D$8),0) | D29: =IF(AND(B29>=1,B29<='01_Supuestos'!$D$10),'01_Supuestos'!$D$9,0) | E29: =C29+D29 | F29: =IF(AND(B29>='01_Supuestos'!$D$19,B29<'01_Supuestos'!$D$19+'01_Supuestos'!$D$17),-'01_Supuestos'!$D$18,0) | G29: =IF(AND(B29>='01_Supuestos'!$D$20,B29<'01_Supuestos'!$D$20+'01_Supuestos'!$D$17),-'01_Supuestos'!$D$18,0) | H29: =IF(B29='01_Supuestos'!$D$22,-'01_Supuestos'!$D$21*'01_Supuestos'!$D$13,0) | I29: =IF(B29='01_Supuestos'!$D$24,-'01_Supuestos'!$D$23,0) | J29: =SUM(F29:I29) | K29: =E29+J29
B30: 17 | C30: =IF(B30=0,'01_Supuestos'!$D$7*(1-'01_Supuestos'!$D$8),0) | D30: =IF(AND(B30>=1,B30<='01_Supuestos'!$D$10),'01_Supuestos'!$D$9,0) | E30: =C30+D30 | F30: =IF(AND(B30>='01_Supuestos'!$D$19,B30<'01_Supuestos'!$D$19+'01_Supuestos'!$D$17),-'01_Supuestos'!$D$18,0) | G30: =IF(AND(B30>='01_Supuestos'!$D$20,B30<'01_Supuestos'!$D$20+'01_Supuestos'!$D$17),-'01_Supuestos'!$D$18,0) | H30: =IF(B30='01_Supuestos'!$D$22,-'01_Supuestos'!$D$21*'01_Supuestos'!$D$13,0) | I30: =IF(B30='01_Supuestos'!$D$24,-'01_Supuestos'!$D$23,0) | J30: =SUM(F30:I30) | K30: =E30+J30
B31: 18 | C31: =IF(B31=0,'01_Supuestos'!$D$7*(1-'01_Supuestos'!$D$8),0) | D31: =IF(AND(B31>=1,B31<='01_Supuestos'!$D$10),'01_Supuestos'!$D$9,0) | E31: =C31+D31 | F31: =IF(AND(B31>='01_Supuestos'!$D$19,B31<'01_Supuestos'!$D$19+'01_Supuestos'!$D$17),-'01_Supuestos'!$D$18,0) | G31: =IF(AND(B31>='01_Supuestos'!$D$20,B31<'01_Supuestos'!$D$20+'01_Supuestos'!$D$17),-'01_Supuestos'!$D$18,0) | H31: =IF(B31='01_Supuestos'!$D$22,-'01_Supuestos'!$D$21*'01_Supuestos'!$D$13,0) | I31: =IF(B31='01_Supuestos'!$D$24,-'01_Supuestos'!$D$23,0) | J31: =SUM(F31:I31) | K31: =E31+J31
B32: 19 | C32: =IF(B32=0,'01_Supuestos'!$D$7*(1-'01_Supuestos'!$D$8),0) | D32: =IF(AND(B32>=1,B32<='01_Supuestos'!$D$10),'01_Supuestos'!$D$9,0) | E32: =C32+D32 | F32: =IF(AND(B32>='01_Supuestos'!$D$19,B32<'01_Supuestos'!$D$19+'01_Supuestos'!$D$17),-'01_Supuestos'!$D$18,0) | G32: =IF(AND(B32>='01_Supuestos'!$D$20,B32<'01_Supuestos'!$D$20+'01_Supuestos'!$D$17),-'01_Supuestos'!$D$18,0) | H32: =IF(B32='01_Supuestos'!$D$22,-'01_Supuestos'!$D$21*'01_Supuestos'!$D$13,0) | I32: =IF(B32='01_Supuestos'!$D$24,-'01_Supuestos'!$D$23,0) | J32: =SUM(F32:I32) | K32: =E32+J32
B33: 20 | C33: =IF(B33=0,'01_Supuestos'!$D$7*(1-'01_Supuestos'!$D$8),0) | D33: =IF(AND(B33>=1,B33<='01_Supuestos'!$D$10),'01_Supuestos'!$D$9,0) | E33: =C33+D33 | F33: =IF(AND(B33>='01_Supuestos'!$D$19,B33<'01_Supuestos'!$D$19+'01_Supuestos'!$D$17),-'01_Supuestos'!$D$18,0) | G33: =IF(AND(B33>='01_Supuestos'!$D$20,B33<'01_Supuestos'!$D$20+'01_Supuestos'!$D$17),-'01_Supuestos'!$D$18,0) | H33: =IF(B33='01_Supuestos'!$D$22,-'01_Supuestos'!$D$21*'01_Supuestos'!$D$13,0) | I33: =IF(B33='01_Supuestos'!$D$24,-'01_Supuestos'!$D$23,0) | J33: =SUM(F33:I33) | K33: =E33+J33 | M33: Nota: no se usa la venta de la casa de Santiago más allá de las UF 15.000 que el enunciado asigna a Villarrica.
B34: 21 | C34: =IF(B34=0,'01_Supuestos'!$D$7*(1-'01_Supuestos'!$D$8),0) | D34: =IF(AND(B34>=1,B34<='01_Supuestos'!$D$10),'01_Supuestos'!$D$9,0) | E34: =C34+D34 | F34: =IF(AND(B34>='01_Supuestos'!$D$19,B34<'01_Supuestos'!$D$19+'01_Supuestos'!$D$17),-'01_Supuestos'!$D$18,0) | G34: =IF(AND(B34>='01_Supuestos'!$D$20,B34<'01_Supuestos'!$D$20+'01_Supuestos'!$D$17),-'01_Supuestos'!$D$18,0) | H34: =IF(B34='01_Supuestos'!$D$22,-'01_Supuestos'!$D$21*'01_Supuestos'!$D$13,0) | I34: =IF(B34='01_Supuestos'!$D$24,-'01_Supuestos'!$D$23,0) | J34: =SUM(F34:I34) | K34: =E34+J34
B35: 22 | C35: =IF(B35=0,'01_Supuestos'!$D$7*(1-'01_Supuestos'!$D$8),0) | D35: =IF(AND(B35>=1,B35<='01_Supuestos'!$D$10),'01_Supuestos'!$D$9,0) | E35: =C35+D35 | F35: =IF(AND(B35>='01_Supuestos'!$D$19,B35<'01_Supuestos'!$D$19+'01_Supuestos'!$D$17),-'01_Supuestos'!$D$18,0) | G35: =IF(AND(B35>='01_Supuestos'!$D$20,B35<'01_Supuestos'!$D$20+'01_Supuestos'!$D$17),-'01_Supuestos'!$D$18,0) | H35: =IF(B35='01_Supuestos'!$D$22,-'01_Supuestos'!$D$21*'01_Supuestos'!$D$13,0) | I35: =IF(B35='01_Supuestos'!$D$24,-'01_Supuestos'!$D$23,0) | J35: =SUM(F35:I35) | K35: =E35+J35
B36: 23 | C36: =IF(B36=0,'01_Supuestos'!$D$7*(1-'01_Supuestos'!$D$8),0) | D36: =IF(AND(B36>=1,B36<='01_Supuestos'!$D$10),'01_Supuestos'!$D$9,0) | E36: =C36+D36 | F36: =IF(AND(B36>='01_Supuestos'!$D$19,B36<'01_Supuestos'!$D$19+'01_Supuestos'!$D$17),-'01_Supuestos'!$D$18,0) | G36: =IF(AND(B36>='01_Supuestos'!$D$20,B36<'01_Supuestos'!$D$20+'01_Supuestos'!$D$17),-'01_Supuestos'!$D$18,0) | H36: =IF(B36='01_Supuestos'!$D$22,-'01_Supuestos'!$D$21*'01_Supuestos'!$D$13,0) | I36: =IF(B36='01_Supuestos'!$D$24,-'01_Supuestos'!$D$23,0) | J36: =SUM(F36:I36) | K36: =E36+J36
B37: 24 | C37: =IF(B37=0,'01_Supuestos'!$D$7*(1-'01_Supuestos'!$D$8),0) | D37: =IF(AND(B37>=1,B37<='01_Supuestos'!$D$10),'01_Supuestos'!$D$9,0) | E37: =C37+D37 | F37: =IF(AND(B37>='01_Supuestos'!$D$19,B37<'01_Supuestos'!$D$19+'01_Supuestos'!$D$17),-'01_Supuestos'!$D$18,0) | G37: =IF(AND(B37>='01_Supuestos'!$D$20,B37<'01_Supuestos'!$D$20+'01_Supuestos'!$D$17),-'01_Supuestos'!$D$18,0) | H37: =IF(B37='01_Supuestos'!$D$22,-'01_Supuestos'!$D$21*'01_Supuestos'!$D$13,0) | I37: =IF(B37='01_Supuestos'!$D$24,-'01_Supuestos'!$D$23,0) | J37: =SUM(F37:I37) | K37: =E37+J37
B38: 25 | C38: =IF(B38=0,'01_Supuestos'!$D$7*(1-'01_Supuestos'!$D$8),0) | D38: =IF(AND(B38>=1,B38<='01_Supuestos'!$D$10),'01_Supuestos'!$D$9,0) | E38: =C38+D38 | F38: =IF(AND(B38>='01_Supuestos'!$D$19,B38<'01_Supuestos'!$D$19+'01_Supuestos'!$D$17),-'01_Supuestos'!$D$18,0) | G38: =IF(AND(B38>='01_Supuestos'!$D$20,B38<'01_Supuestos'!$D$20+'01_Supuestos'!$D$17),-'01_Supuestos'!$D$18,0) | H38: =IF(B38='01_Supuestos'!$D$22,-'01_Supuestos'!$D$21*'01_Supuestos'!$D$13,0) | I38: =IF(B38='01_Supuestos'!$D$24,-'01_Supuestos'!$D$23,0) | J38: =SUM(F38:I38) | K38: =E38+J38
B39: 26 | C39: =IF(B39=0,'01_Supuestos'!$D$7*(1-'01_Supuestos'!$D$8),0) | D39: =IF(AND(B39>=1,B39<='01_Supuestos'!$D$10),'01_Supuestos'!$D$9,0) | E39: =C39+D39 | F39: =IF(AND(B39>='01_Supuestos'!$D$19,B39<'01_Supuestos'!$D$19+'01_Supuestos'!$D$17),-'01_Supuestos'!$D$18,0) | G39: =IF(AND(B39>='01_Supuestos'!$D$20,B39<'01_Supuestos'!$D$20+'01_Supuestos'!$D$17),-'01_Supuestos'!$D$18,0) | H39: =IF(B39='01_Supuestos'!$D$22,-'01_Supuestos'!$D$21*'01_Supuestos'!$D$13,0) | I39: =IF(B39='01_Supuestos'!$D$24,-'01_Supuestos'!$D$23,0) | J39: =SUM(F39:I39) | K39: =E39+J39
B40: 27 | C40: =IF(B40=0,'01_Supuestos'!$D$7*(1-'01_Supuestos'!$D$8),0) | D40: =IF(AND(B40>=1,B40<='01_Supuestos'!$D$10),'01_Supuestos'!$D$9,0) | E40: =C40+D40 | F40: =IF(AND(B40>='01_Supuestos'!$D$19,B40<'01_Supuestos'!$D$19+'01_Supuestos'!$D$17),-'01_Supuestos'!$D$18,0) | G40: =IF(AND(B40>='01_Supuestos'!$D$20,B40<'01_Supuestos'!$D$20+'01_Supuestos'!$D$17),-'01_Supuestos'!$D$18,0) | H40: =IF(B40='01_Supuestos'!$D$22,-'01_Supuestos'!$D$21*'01_Supuestos'!$D$13,0) | I40: =IF(B40='01_Supuestos'!$D$24,-'01_Supuestos'!$D$23,0) | J40: =SUM(F40:I40) | K40: =E40+J40
B41: 28 | C41: =IF(B41=0,'01_Supuestos'!$D$7*(1-'01_Supuestos'!$D$8),0) | D41: =IF(AND(B41>=1,B41<='01_Supuestos'!$D$10),'01_Supuestos'!$D$9,0) | E41: =C41+D41 | F41: =IF(AND(B41>='01_Supuestos'!$D$19,B41<'01_Supuestos'!$D$19+'01_Supuestos'!$D$17),-'01_Supuestos'!$D$18,0) | G41: =IF(AND(B41>='01_Supuestos'!$D$20,B41<'01_Supuestos'!$D$20+'01_Supuestos'!$D$17),-'01_Supuestos'!$D$18,0) | H41: =IF(B41='01_Supuestos'!$D$22,-'01_Supuestos'!$D$21*'01_Supuestos'!$D$13,0) | I41: =IF(B41='01_Supuestos'!$D$24,-'01_Supuestos'!$D$23,0) | J41: =SUM(F41:I41) | K41: =E41+J41
B42: 29 | C42: =IF(B42=0,'01_Supuestos'!$D$7*(1-'01_Supuestos'!$D$8),0) | D42: =IF(AND(B42>=1,B42<='01_Supuestos'!$D$10),'01_Supuestos'!$D$9,0) | E42: =C42+D42 | F42: =IF(AND(B42>='01_Supuestos'!$D$19,B42<'01_Supuestos'!$D$19+'01_Supuestos'!$D$17),-'01_Supuestos'!$D$18,0) | G42: =IF(AND(B42>='01_Supuestos'!$D$20,B42<'01_Supuestos'!$D$20+'01_Supuestos'!$D$17),-'01_Supuestos'!$D$18,0) | H42: =IF(B42='01_Supuestos'!$D$22,-'01_Supuestos'!$D$21*'01_Supuestos'!$D$13,0) | I42: =IF(B42='01_Supuestos'!$D$24,-'01_Supuestos'!$D$23,0) | J42: =SUM(F42:I42) | K42: =E42+J42
...

Sheet 03_Estrategias
B2: Estrategias activas: resultados y comparación con su benchmark
B3: Backtests point-in-time (codigo/estrategias.py). Métricas vs T-Bills (BIL).
B5: Estrategia | C5: Benchmark | D5: CAGR | E5: Volatilidad | F5: Sharpe | G5: Sortino | H5: Beta | I5: Alfa CAPM | J5: Máx. caída | K5: VaR 95% mensual | L5: CVaR 95% mensual | M5: Tracking error | N5: Information ratio
B6: Momentum en acciones | C6: QMOM | D6: 0.15020497 | E6: 0.25743058 | F6: 0.59204502 | G6: 0.60948126 | H6: 1.1188392 | I6: 0.0052543027 | J6: -0.37424195 | K6: 0.08435479 | L6: 0.15230602 | M6: 0.18970735 | N6: 0.2045562
B7: Momentum en acciones (2013-2026) | C7: — | D7: 0.16184388 | E7: 0.23760947 | F7: 0.68444486 | G7: 0.71200836 | H7: 1.098336 | I7: 0.014494475 | J7: -0.37424195 | K7: 0.076536156 | L7: 0.13639034
B8: Low-Volatility | C8: SPLV | D8: 0.095662872 | E8: 0.12269648 | F8: 0.63607755 | G8: 0.648193 | H8: 0.51467084 | I8: 0.010351998 | J8: -0.17847822 | K8: 0.051721213 | L8: 0.069188152 | M8: 0.044320618 | N8: 0.1803673
B9: Low-Volatility (2013-2026) | C9: — | D9: 0.10716073 | E9: 0.11960375 | F9: 0.77798309 | G9: 0.79472747 | H9: 0.54262495 | I9: 0.019864122 | J9: -0.17847822 | K9: 0.049732321 | L9: 0.065313838
B10: Momentum en commodities | C10: DJP | D10: 0.10597376 | E10: 0.19156642 | F10: 0.51228232 | G10: 0.50110944 | H10: 0.16737434 | I10: 0.076122051 | J10: -0.31436389 | K10: 0.067549483 | L10: 0.11731172 | M10: 0.19625645 | N10: 0.12202883
B11: Momentum en commodities (2013-2026) | C11: — | D11: 0.07945914 | E11: 0.16986919 | F11: 0.43951038 | G11: 0.39699134 | H11: 0.14589543 | I11: 0.054981886 | J11: -0.31436389 | K11: 0.065285812 | L11: 0.10592122

Sheet 04_Datos_Mensuales
B2: Retornos mensuales nominales en USD (ene-2013 a ago-2026, 164 meses)
B3: Fuente: backtests point-in-time (estrategias activas) y Yahoo Finance ajustado por dividendos (ETF).
B5: Fecha | C5: SPY | D5: TLH | E5: VCLT | F5: MOM_CMD | G5: MOM_EQ | H5: LOW_VOL | I5: BM_SPY | J5: BM_TLH | K5: BM_VCLT | L5: BM_MOM_CMD | M5: BM_MOM_EQ | N5: BM_LOW_VOL
B6: 41305 | C6: 0.051190367 | D6: -0.019946044 | E6: -0.022715109 | F6: 0 | G6: 0.089626037 | H6: 0.062771072 | I6: 0.051190367 | J6: -0.019946044 | K6: -0.022715109 | L6: 0.022974626 | N6: 0.048571467
B7: 41333 | C7: 0.012758954 | D7: 0.011792005 | E7: 0.017338562 | F7: 0 | G7: 0.03185968 | H7: 0.044618312 | I7: 0.012758954 | J7: 0.011792005 | K7: 0.017338562 | L7: -0.045862853 | N7: 0.028293445
B8: 41364 | C8: 0.037970801 | D8: 0.0037306672 | E8: -0.010950841 | F8: 0 | G8: 0.065716104 | H8: 0.056548485 | I8: 0.037970801 | J8: 0.0037306672 | K8: -0.010950841 | L8: 0.0064419801 | N8: 0.048913137
B9: 41394 | C9: 0.019212412 | D9: 0.024770757 | E9: 0.04499772 | F9: -0.00021867084 | G9: -0.015213923 | H9: 0.027757943 | I9: 0.019212412 | J9: 0.024770757 | K9: 0.04499772 | L9: -0.028311121 | N9: 0.037708482
B10: 41425 | C10: 0.023610226 | D10: -0.043407618 | E10: -0.058050804 | F10: 0.00021871867 | G10: 0.060320629 | H10: -0.032361389 | I10: 0.023610226 | J10: -0.043407618 | K10: -0.058050804 | L10: -0.029389405 | N10: -0.036103903
B11: 41455 | C11: -0.013345132 | D11: -0.029673135 | E11: -0.044215077 | F11: -0.00021867084 | G11: -0.067673192 | H11: 0.014763864 | I11: -0.013345132 | J11: -0.029673135 | K11: -0.044215077 | L11: -0.047507169 | N11: 0.0078426212
B12: 41486 | C12: 0.051677434 | D12: -0.0093271014 | E12: 0.0098349889 | F12: 0 | G12: 0.080885794 | H12: 0.032179953 | I12: 0.051677434 | J12: -0.0093271014 | K12: 0.0098349889 | L12: 0.014250387 | N12: 0.041885904
B13: 41517 | C13: -0.029992479 | D13: -0.0096968603 | E13: -0.014606454 | F13: 0 | G13: -0.0013543687 | H13: -0.049001911 | I13: -0.029992479 | J13: -0.0096968603 | K13: -0.014606454 | L13: 0.039178623 | N13: -0.050410405
B14: 41547 | C14: 0.031646442 | D14: 0.014341136 | E14: 0.0057194965 | F14: -0.00021809286 | G14: 0.080273411 | H14: 0.0083171652 | I14: 0.031646442 | J14: 0.014341136 | K14: 0.0057194965 | L14: -0.031201269 | N14: 0.020403314
B15: 41578 | C15: 0.046306539 | D15: 0.010131842 | E15: 0.025024043 | F15: -0.00021866206 | G15: 0.043752681 | H15: 0.045099769 | I15: 0.046306539 | J15: 0.010131842 | K15: 0.025024043 | L15: -0.017176581 | N15: 0.046421035
B16: 41608 | C16: 0.029637976 | D16: -0.018115207 | E16: -0.0092874518 | F16: -0.00021860553 | G16: 0.038651325 | H16: 0.020823632 | I16: 0.029637976 | J16: -0.018115207 | K16: -0.0092874518 | L16: -0.0084652531 | N16: 0.011071235
B17: 41639 | C17: 0.025926139 | D17: -0.018351631 | E17: 0.0084642509 | F17: 0 | G17: 0.00099023221 | H17: -7.9224467e-05 | I17: 0.025926139 | J17: -0.018351631 | K17: 0.0084642509 | L17: 0.012117836 | N17: 0.011263785
... B41: 42369 | C41: -0.017282866 | D41: -0.0036125523 | E41: -0.012810248 | F41: -0.00021934965 | G41: -0.017960007 | H41: 0.0042264815 | I41: -0.017282866 | J41: -0.0036125523 | K41: -0.012810248 | L41: -0.035056211 | N41: -0.0015724577
B42: 42400 | C42: -0.049786092 | D42: 0.037031723 | E42: -0.0040387659 | F42: 0.00021939778 | G42: -0.084344391 | H42: 0.0098335074 | I42: -0.049786092 | J42: 0.037031723 | K42: -0.0040387659 | L42: -0.021425203 | M42: -0.079949191 | N42: -0.017563886
B43: 42429 | C43: -0.00082648481 | D43: 0.018573408 | E43: 0.010437223 | F43: 0 | G43: -0.011013715 | H43: 0.024992585 | I43: -0.00082648481 | J43: 0.018573408 | K43: 0.010437223 | L43: -0.016658752 | M43: 0.0029885373 | N43: 0.009886442
B44: 42460 | C44: 0.067266393 | D44: 0.0012948835 | E44: 0.063867295 | F44: 0 | G44: 0.0663703 | H44: 0.054874855 | I44: 0.067266393 | J44: 0.0012948835 | K44: 0.063867295 | L44: 0.040658285 | M44: 0.036855119 | N44: 0.059913697
B45: 42490 | C45: 0.0039411468 | D45: -0.0037655756 | E45: 0.023222589 | F45: 0.00043702647 | G45: -0.027288175 | H45: -0.01241946 | I45: 0.0039411468 | J45: -0.0037655756 | K45: 0.023222589 | L45: 0.099069728 | M45: 0.0053494866 | N45: -0.0079695344
B46: 42521 | C46: 0.017011753 | D46: 0.002910602 | E46: -0.0032898019 | F46: -0.0005 | G46: 0.037931803 | H46: 0.0050305972 | I46: 0.017011753 | J46: 0.002910602 | K46: -0.0032898019 | L46: -0.0059246464 | M46: 0.029903556 | N46: 0.016785142
B47: 42551 | C47: 0.0034757506 | D47: 0.041837344 | E47: 0.047372083 | F47: 0.17527361 | G47: 0.086549229 | H47: 0.069309267 | I47: 0.0034757506 | J47: 0.041837344 | K47: 0.047372083 | L47: 0.052788411 | M47: -0.011313558 | N47: 0.057407778
B48: 42582 | C48: 0.036471032 | D48: 0.0065715988 | E48: 0.025504639 | F48: -6.2337392e-05 | G48: 0.038163055 | H48: 0.0069997039 | I48: 0.036471032 | J48: 0.0065715988 | K48: 0.025504639 | L48: -0.063485634 | M48: 0.061132723 | N48: 0.0022344482
B49: 42613 | C49: 0.0011975481 | D49: -0.01119454 | E49: 0.001588322 | F49: -0.058900473 | G49: -0.044282921 | H49: -0.035277078 | I49: 0.0011975481 | J49: -0.01119454 | K49: 0.001588322 | L49: -0.018134718 | M49: -0.017030735 | N49: -0.01905834
B50: 42643 | C50: 5.8178275e-05 | D50: -0.0031590987 | E50: -0.0044726807 | F50: 0.027088119 | G50: 0.016526723 | H50: -0.003027497 | I50: 5.8178275e-05 | J50: -0.0031590987 | K50: -0.0044726807 | L50: 0.032102003 | M50: 0.021029792 | N50: -0.0089177879
B51: 42674 | C51: -0.017337189 | D51: -0.022789989 | E51: -0.024880859 | F51: -0.068082494 | G51: -0.026207558 | H51: -0.016916962 | I51: -0.017337189 | J51: -0.022789989 | K51: -0.024880859 | L51: -0.002982518 | M51: -0.032940868 | N51: -0.023238628
B52: 42704 | C52: 0.036838454 | D52: -0.052447516 | E52: -0.048950083 | F52: -0.00043727985 | G52: 0.049015584 | H52: 0.0026192231 | I52: 0.036838454 | J52: -0.052447516 | K52: -0.048950083 | L52: 0.010683761 | M52: 0.05132529 | N52: 0.0052611378
B53: 42735 | C53: 0.02027193 | D53: -0.0029820161 | E53: 0.021434847 | F53: -0.00028142115 | G53: 0.021569093 | H53: 0.043166392 | I53: 0.02027193 | J53: -0.0029820161 | K53: 0.021434847 | L53: 0.02452431 | M53: -0.011165433 | N53: 0.025924078
... B169: 46265 | C169: 0.029878245 | D169: 0.011740824 | E169: 0.0099107153 | F169: 0.0021584228 | G169: 0.36229975 | H169: -0.015341132 | I169: 0.029878245 | J169: 0.011740824 | K169: 0.0099107153 | L169: 0.083790572 | M169: -0.0092893623 | N169: -0.018351058

Sheet 05_Markowitz
B2: Markowitz: estadísticos con fórmulas y cartera de máximo Sharpe histórico
B3: Referencia: optimizar con medias históricas sobreajusta (ver walk-forward en 09). La recomendación es Black-Litterman (06).
B5: Activo | C5: Retorno anual | D5: Volatilidad anual | E5: Peso Markowitz (máx. Sharpe, SLSQP) | F5: Peso aprobado (BL)
B6: S&P 500 (SPY) | C6: =AVERAGE('04_Datos_Mensuales'!$C$6:$C$169)*12 | D6: =_xlfn.STDEV.S('04_Datos_Mensuales'!$C$6:$C$169)*SQRT(12) | E6: 0.45320405 | F6: 0.3789
B7: Tesoro EE.UU. 10-20 años (TLH) | C7: =AVERAGE('04_Datos_Mensuales'!$D$6:$D$169)*12 | D7: =_xlfn.STDEV.S('04_Datos_Mensuales'!$D$6:$D$169)*SQRT(12) | E7: 0.08 | F7: 0.1687
B8: Corporativos largo plazo (VCLT) | C8: =AVERAGE('04_Datos_Mensuales'!$E$6:$E$169)*12 | D8: =_xlfn.STDEV.S('04_Datos_Mensuales'!$E$6:$E$169)*SQRT(12) | E8: 0.08 | F8: 0.146
B9: Momentum en commodities | C9: =AVERAGE('04_Datos_Mensuales'!$F$6:$F$169)*12 | D9: =_xlfn.STDEV.S('04_Datos_Mensuales'!$F$6:$F$169)*SQRT(12) | E9: 0.18416883 | F9: 0.0611
B10: Momentum en acciones | C10: =AVERAGE('04_Datos_Mensuales'!$G$6:$G$169)*12 | D10: =_xlfn.STDEV.S('04_Datos_Mensuales'!$G$6:$G$169)*SQRT(12) | E10: 0.023067044 | F10: 0.0706
B11: Low-Volatility | C11: =AVERAGE('04_Datos_Mensuales'!$H$6:$H$169)*12 | D11: =_xlfn.STDEV.S('04_Datos_Mensuales'!$H$6:$H$169)*SQRT(12) | E11: 0.17956007 | F11: 0.1746
B13: Matriz de covarianza anual (fórmulas COVARIANCE.S)
C14: S&P 500 (SPY) | D14: Tesoro EE.UU. 10-20 añ | E14: Corporativos largo pla | F14: Momentum en commoditie | G14: Momentum en acciones | H14: Low-Volatility
B15: S&P 500 (SPY) | C15: =_xlfn.COVARIANCE.S('04_Datos_Mensuales'!$C$6:$C$169,'04_Datos_Mensuales'!$C$6:$C$169)*12 | D15: =_xlfn.COVARIANCE.S('04_Datos_Mensuales'!$C$6:$C$169,'04_Datos_Mensuales'!$D$6:$D$169)*12 | E15: =_xlfn.COVARIANCE.S('04_Datos_Mensuales'!$C$6:$C$169,'04_Datos_Mensuales'!$E$6:$E$169)*12 | F15: =_xlfn.COVARIANCE.S('04_Datos_Mensuales'!$C$6:$C$169,'04_Datos_Mensuales'!$F$6:$F$169)*12 | G15: =_xlfn.COVARIANCE.S('04_Datos_Mensuales'!$C$6:$C$169,'04_Datos_Mensuales'!$G$6:$G$169)*12 | H15: =_xlfn.COVARIANCE.S('04_Datos_Mensuales'!$C$6:$C$169,'04_Datos_Mensuales'!$H$6:$H$169)*12
B16: Tesoro EE.UU. 10-20 años (TLH) | C16: =_xlfn.COVARIANCE.S('04_Datos_Mensuales'!$D$6:$D$169,'04_Datos_Mensuales'!$C$6:$C$169)*12 | D16: =_xlfn.COVARIANCE.S('04_Datos_Mensuales'!$D$6:$D$169,'04_Datos_Mensuales'!$D$6:$D$169)*12 | E16: =_xlfn.COVARIANCE.S('04_Datos_Mensuales'!$D$6:$D$169,'04_Datos_Mensuales'!$E$6:$E$169)*12 | F16: =_xlfn.COVARIANCE.S('04_Datos_Mensuales'!$D$6:$D$169,'04_Datos_Mensuales'!$F$6:$F$169)*12 | G16: =_xlfn.COVARIANCE.S('04_Datos_Mensuales'!$D$6:$D$169,'04_Datos_Mensuales'!$G$6:$G$169)*12 | H16: =_xlfn.COVARIANCE.S('04_Datos_Mensuales'!$D$6:$D$169,'04_Datos_Mensuales'!$H$6:$H$169)*12
B17: Corporativos largo plazo (VCLT) | C17: =_xlfn.COVARIANCE.S('04_Datos_Mensuales'!$E$6:$E$169,'04_Datos_Mensuales'!$C$6:$C$169)*12 | D17: =_xlfn.COVARIANCE.S('04_Datos_Mensuales'!$E$6:$E$169,'04_Datos_Mensuales'!$D$6:$D$169)*12 | E17: =_xlfn.COVARIANCE.S('04_Datos_Mensuales'!$E$6:$E$169,'04_Datos_Mensuales'!$E$6:$E$169)*12 | F17: =_xlfn.COVARIANCE.S('04_Datos_Mensuales'!$E$6:$E$169,'04_Datos_Mensuales'!$F$6:$F$169)*12 | G17: =_xlfn.COVARIANCE.S('04_Datos_Mensuales'!$E$6:$E$169,'04_Datos_Mensuales'!$G$6:$G$169)*12 | H17: =_xlfn.COVARIANCE.S('04_Datos_Mensuales'!$E$6:$E$169,'04_Datos_Mensuales'!$H$6:$H$169)*12
B18: Momentum en commodities | C18: =_xlfn.COVARIANCE.S('04_Datos_Mensuales'!$F$6:$F$169,'04_Datos_Mensuales'!$C$6:$C$169)*12 | D18: =_xlfn.COVARIANCE.S('04_Datos_Mensuales'!$F$6:$F$169,'04_Datos_Mensuales'!$D$6:$D$169)*12 | E18: =_xlfn.COVARIANCE.S('04_Datos_Mensuales'!$F$6:$F$169,'04_Datos_Mensuales'!$E$6:$E$169)*12 | F18: =_xlfn.COVARIANCE.S('04_Datos_Mensuales'!$F$6:$F$169,'04_Datos_Mensuales'!$F$6:$F$169)*12 | G18: =_xlfn.COVARIANCE.S('04_Datos_Mensuales'!$F$6:$F$169,'04_Datos_Mensuales'!$G$6:$G$169)*12 | H18: =_xlfn.COVARIANCE.S('04_Datos_Mensuales'!$F$6:$F$169,'04_Datos_Mensuales'!$H$6:$H$169)*12
B19: Momentum en acciones | C19: =_xlfn.COVARIANCE.S('04_Datos_Mensuales'!$G$6:$G$169,'04_Datos_Mensuales'!$C$6:$C$169)*12 | D19: =_xlfn.COVARIANCE.S('04_Datos_Mensuales'!$G$6:$G$169,'04_Datos_Mensuales'!$D$6:$D$169)*12 | E19: =_xlfn.COVARIANCE.S('04_Datos_Mensuales'!$G$6:$G$169,'04_Datos_Mensuales'!$E$6:$E$169)*12 | F19: =_xlfn.COVARIANCE.S('04_Datos_Mensuales'!$G$6:$G$169,'04_Datos_Mensuales'!$F$6:$F$169)*12 | G19: =_xlfn.COVARIANCE.S('04_Datos_Mensuales'!$G$6:$G$169,'04_Datos_Mensuales'!$G$6:$G$169)*12 | H19: =_xlfn.COVARIANCE.S('04_Datos_Mensuales'!$G$6:$G$169,'04_Datos_Mensuales'!$H$6:$H$169)*12
B20: Low-Volatility | C20: =_xlfn.COVARIANCE.S('04_Datos_Mensuales'!$H$6:$H$169,'04_Datos_Mensuales'!$C$6:$C$169)*12 | D20: =_xlfn.COVARIANCE.S('04_Datos_Mensuales'!$H$6:$H$169,'04_Datos_Mensuales'!$D$6:$D$169)*12 | E20: =_xlfn.COVARIANCE.S('04_Datos_Mensuales'!$H$6:$H$169,'04_Datos_Mensuales'!$E$6:$E$169)*12 | F20: =_xlfn.COVARIANCE.S('04_Datos_Mensuales'!$H$6:$H$169,'04_Datos_Mensuales'!$F$6:$F$169)*12 | G20: =_xlfn.COVARIANCE.S('04_Datos_Mensuales'!$H$6:$H$169,'04_Datos_Mensuales'!$G$6:$G$169)*12 | H20: =_xlfn.COVARIANCE.S('04_Datos_Mensuales'!$H$6:$H$169,'04_Datos_Mensuales'!$H$6:$H$169)*12
B23: Cartera Markowitz
B24: Retorno anual | C24: {=SUMPRODUCT(E6:E11,C6:C11)}
B25: Volatilidad anual | C25: {=SQRT(MMULT(TRANSPOSE(E6:E11),MMULT(C15:H20,E6:E11)))}
B26: Sharpe (rf = 0, misma convención del optimizador) | C26: =C24/C25
B27: Cartera Pesos aprobados
B28: Retorno anual | C28: {=SUMPRODUCT(F6:F11,C6:C11)}
B29: Volatilidad anual | C29: {=SQRT(MMULT(TRANSPOSE(F6:F11),MMULT(C15:H20,F6:F11)))}
B30: Sharpe (rf = 0, misma convención del optimizador) | C30: =C28/C29
B32: Restricciones: suma = 100%; núcleo (SPY+TLH+VCLT) entre 60% y 70%; TLH y VCLT ≥ 8%; sin ventas cortas.
B33: Chequeo núcleo Markowitz | C33: =IF(AND(SUM(E6:E8)>=0.6-1E-6,SUM(E6:E8)<=0.7+1E-6,ABS(SUM(E6:E11)-1)<1E-6),"OK","REVISAR")

Sheet 06_Black_Litterman
B2: Black-Litterman: equilibrio + vistas → retornos esperados y cartera recomendada
B3: π = δ·Σ·w_eq ; μ_BL = [(τΣ)⁻¹ + PᵀΩ⁻¹P]⁻¹ [(τΣ)⁻¹π + PᵀΩ⁻¹Q] ; Ω = diag(P·τΣ·Pᵀ). Fórmulas matriciales vivas.
B5: Activo | C5: Volatilidad | D5: Prior w_eq (1/vol normalizado) | E5: π implícito | F5: μ Black-Litterman | G5: Peso BL recalibrado (SLSQP) | H5: Peso aprobado | I5: Diferencia (pp)
B6: S&P 500 (SPY) | C6: ='05_Markowitz'!D6 | D6: =(1/C6)/SUMPRODUCT(1/$C$6:$C$11) | E6: {='01_Supuestos'!$D$29*MMULT('05_Markowitz'!$C$15:$H$20,D6:D11)} | F6: =C31 | G6: 0.37268829 | H6: ='05_Markowitz'!F6 | I6: =(G6-H6)*100
B7: Tesoro EE.UU. 10-20 años (TLH) | C7: ='05_Markowitz'!D7 | D7: =(1/C7)/SUMPRODUCT(1/$C$6:$C$11) | F7: =C32 | G7: 0.17089026 | H7: ='05_Markowitz'!F7 | I7: =(G7-H7)*100
B8: Corporativos largo plazo (VCLT) | C8: ='05_Markowitz'!D8 | D8: =(1/C8)/SUMPRODUCT(1/$C$6:$C$11) | F8: =C33 | G8: 0.14842799 | H8: ='05_Markowitz'!F8 | I8: =(G8-H8)*100
B9: Momentum en commodities | C9: ='05_Markowitz'!D9 | D9: =(1/C9)/SUMPRODUCT(1/$C$6:$C$11) | F9: =C34 | G9: 0.065944585 | H9: ='05_Markowitz'!F9 | I9: =(G9-H9)*100
B10: Momentum en acciones | C10: ='05_Markowitz'!D10 | D10: =(1/C10)/SUMPRODUCT(1/$C$6:$C$11) | F10: =C35 | G10: 0.070231253 | H10: ='05_Markowitz'!F10 | I10: =(G10-H10)*100
B11: Low-Volatility | C11: ='05_Markowitz'!D11 | D11: =(1/C11)/SUMPRODUCT(1/$C$6:$C$11) | F11: =C36 | G11: 0.17181762 | H11: ='05_Markowitz'!F11 | I11: =(G11-H11)*100
B13: Vistas del inversionista
B14: Vista | C14: Tipo | D14: SPY | E14: TLH | F14: VCLT | G14: MOM_CMD | H14: MOM_EQ | I14: LOW_VOL | J14: Q (retorno) | K14: Fundamento
B15: Vista 1 | C15: Absoluta | D15: 1 | E15: 0 | F15: 0 | G15: 0 | H15: 0 | I15: 0 | J15: 0.06 | K15: Prima por riesgo accionaria de largo plazo
B16: Vista 2 | C16: Relativa | D16: 0 | E16: 0 | F16: 0 | G16: -1 | H16: 0 | I16: 1 | J16: 0.02 | K16: Low-Vol supera a commodities en 2 pp
B18: τΣ
C19: {='01_Supuestos'!$D$30*'05_Markowitz'!$C$15:$H$20}
B26: Ω (diagonal)
C27: {=MMULT(D15:I16,MMULT(C19:H24,TRANSPOSE(D15:I16)))*{1,0;0,1}}
B30: μ_BL calculado
B31: S&P 500 (SPY) | C31: {=MMULT(MINVERSE(MINVERSE(C19:H24)+MMULT(TRANSPOSE(D15:I16),MMULT(MINVERSE(C27:D28),D15:I16))),MMULT(MINVERSE(C19:H24),E6:E11)+MMULT(TRANSPOSE(D15:I16),MMULT(MINVERSE(C27:D28),J15:J16)))}
B32: Tesoro EE.UU. 10-20 años (TLH)
B33: Corporativos largo plazo (VCLT)
B34: Momentum en commodities
B35: Momentum en acciones
B36: Low-Volatility
B39: Cartera recomendada (pesos aprobados)
B40: Retorno esperado (μ_BL) | C40: {=SUMPRODUCT(H6:H11,F6:F11)}
B41: Volatilidad | C41: ='05_Markowitz'!C29
B42: Sharpe sobre μ_BL | C42: =C40/C41
B43: Núcleo pasivo (SPY+TLH+VCLT) | C43: =SUM(H6:H8)
B44: Chequeo: Σ pesos = 100% | C44: =IF(ABS(SUM(H6:H11)-1)<0.0005,"OK","REVISAR")
B46: Lectura: los pesos recalibrados con los datos corregidos difieren en menos de 0,7 pp de los aprobados (dentro de la banda de rebalanceo de ±2 pp): se mantienen los pesos aprobados, que ya están implementados.
B48: Aversión al riesgo
B49: Concepto | C49: Valor
B50: A del inversionista de mercado (S&P 500, 2013-2026) | C50: 6.6789023
B51: A implícito de la cartera BL (μ_BL / σ²) | C51: 3.335814
B52: δ usado en Black-Litterman | C52: 2.5
B54: Contribución al riesgo (pesos aprobados): w_i·(Σw)_i / w'Σw
B55: Activo | C55: Peso | D55: Contribución marginal (Σw)_i | E55: Contribución al riesgo (%)
B56: S&P 500 (SPY) | C56: ='05_Markowitz'!F6 | D56: {=MMULT('05_Markowitz'!C15:H20,'05_Markowitz'!F6:F11)} | E56: =C56*D56/SUMPRODUCT($C$56:$C$61,$D$56:$D$61)
B57: Tesoro EE.UU. 10-20 años (TLH) | C57: ='05_Markowitz'!F7 | E57: =C57*D57/SUMPRODUCT($C$56:$C$61,$D$56:$D$61)
...

Sheet 07_Benchmark_Metricas
B2: Benchmark de política, métricas y tracking error
B3: Benchmark compuesto en USD, ponderado por los pesos aprobados; cada sleeve contra un índice invertible de su mismo universo.
B5: Sleeve | C5: Peso | D5: Benchmark
B6: S&P 500 (SPY) | C6: 0.3789 | D6: S&P 500 (SPY)
B7: Tesoro EE.UU. 10-20 años (TLH) | C7: 0.1687 | D7: ICE U.S. Treasury 10-20 Year (TLH)
B8: Corporativos largo plazo (VCLT) | C8: 0.146 | D8: Bloomberg U.S. Long Corporate (VCLT)
B9: Momentum en commodities | C9: 0.0611 | D9: Bloomberg Commodity Index Total Return (DJP)
B10: Momentum en acciones | C10: 0.0706 | D10: Alpha Architect U.S. Quantitative Momentum (QMOM)
B11: Low-Volatility | C11: 0.1746 | D11: S&P 500 Low Volatility Index (SPLV)
B13: Métricas (USD nominal; Sharpe vs T-Bills)
B14: Período | C14: Serie | D14: CAGR | E14: Volatilidad | F14: Sharpe | G14: Sortino | H14: Treynor | I14: Beta | J14: Alfa CAPM | K14: Máx. caída | L14: Calmar | M14: VaR 95% mensual | N14: CVaR 95% mensual | O14: Tracking error | P14: Information ratio
B15: 2016-2026 | C15: Cartera Nexum | D15: 0.099022251 | E15: 0.10644139 | F15: 0.74499517 | G15: 0.63745823 | H15: 0.12274211 | I15: 0.64605636 | J15: -0.0056747361 | K15: -0.2047528 | L15: 0.48361855 | M15: 0.045968017 | N15: 0.062017676 | O15: 0.020629949 | P15: 0.27138806
B16: 2016-2026 | C16: Benchmark de política | D16: 0.092672048 | E16: 0.10863743 | F16: 0.67839972 | G16: 0.57527763 | H16: 0.10895763 | I16: 0.67640604 | J16: -0.015265222 | K16: -0.20325419 | L16: 0.45594163 | M16: 0.044602398 | N16: 0.065040775 | O16: 0
B17: 2016-2026 | C17: Cartera actual AGF 85/15 | D17: 0.12652637 | E17: 0.12919085 | F17: 0.82747817 | G17: 0.72856854 | H17: 0.12527037 | I17: 0.85337504 | J17: -0.0053381965 | K17: -0.22646999 | L17: 0.55868934 | M17: 0.056869858 | N17: 0.077159605 | O17: 0.041010896 | P17: 0.80961435
B18: 2016-2026 | C18: S&P 500 (SPY) | D18: 0.15086163 | E18: 0.15089979 | F18: 0.87161003 | G18: 0.78082749 | H18: 0.13152577 | I18: 1 | J18: -6.2450045e-17 | K18: -0.23927184 | L18: 0.63050309 | M18: 0.067237758 | N18: 0.089123578 | O18: 0.061386455 | P18: 0.94200206
B19: 2013-2026 | C19: Cartera Nexum | D19: 0.099933609 | E19: 0.099130185 | F19: 0.84976461 | G19: 0.7459042 | H19: 0.13243443 | I19: 0.63606814 | J19: -0.0015512318 | K19: -0.2047528 | L19: 0.48806956 | M19: 0.040864359 | N19: 0.057370065
B20: 2013-2026 | C20: Cartera actual AGF 85/15 | D20: 0.12203584 | E20: 0.12326656 | F20: 0.86266988 | G20: 0.78296918 | H20: 0.12462213 | I20: 0.85328622 | J20: -0.0045878482 | K20: -0.22646999 | L20: 0.53886098 | M20: 0.051129667 | N20: 0.074228782
B21: 2013-2026 | C21: S&P 500 (SPY) | D21: 0.15060975 | E21: 0.14210531 | F21: 0.94910749 | G21: 0.87148108 | H21: 0.13487322 | I21: 1 | J21: -2.0816682e-17 | K21: -0.23927184 | L21: 0.62945038 | M21: 0.060451937 | N21: 0.083176312
B24: Tracking error: derivación y situación actual
B25: Concepto | C25: Valor
B26: TE ex-ante, pesos aprobados (2016-2026) | C26: 0.020629949
B27: TE últimos 36 meses | C27: 0.02483686
B28: Alfa objetivo anual | C28: 0.015
B29: Information ratio objetivo | C29: 0.5
B30: TE objetivo = alfa / IR | C30: 0.03
B31: TE máximo (alfa 2% / IR 0,5) | C31: 0.04
B32: TE del sleeve S&P 500 (SPY) vs su benchmark | C32: 0
B33: TE del sleeve Tesoro EE.UU. 10-20 años (TLH) vs su benchmark | C33: 0
B34: TE del sleeve Corporativos largo plazo (VCLT) vs su benchmark | C34: 0
B35: TE del sleeve Momentum en commodities vs su benchmark | C35: 0.19625645
B36: TE del sleeve Momentum en acciones vs su benchmark | C36: 0.18970735
B37: TE del sleeve Low-Volatility vs su benchmark | C37: 0.044320618

Sheet 08_Montecarlo
B2: Montecarlo: probabilidad de cumplir los objetivos (20.000 escenarios, 50 años)
B3: Bootstrap mensual. Prospectivo: misma volatilidad y correlaciones, medias ajustadas a supuestos de mercado. UF: tipo de cambio real sin tendencia, con su volatilidad y correlación histórica.
B5: Cartera | C5: Escenario | D5: Moneda | E5: Retorno real anual | F5: P(Educación) | G5: P(Villarrica) | H5: P(Herencia) | I5: P(3 objetivos) | J5: Saldo año 25 P10 | K5: Saldo año 25 P50 | L5: Saldo año 25 P90 | M5: Saldo año 50 P10 | N5: Saldo año 50 P50 | O5: Máx. caída mediana | P5: Máx. caída peor 5% | Q5: Unidad
B6: Nexum | C6: Histórico 2013-2026 | D6: USD | E6: 0.078368404 | F6: 1 | G6: 0.98135 | H6: 0.95955 | I6: 0.95955 | J6: 707660.28 | K6: 1320710.1 | L6: 2423866.1 | M6: 1311231.8 | N6: 5448079 | O6: -0.24062234 | P6: -0.36194799 | Q6: USD reales
B7: Nexum | C7: Histórico 2013-2026 | D7: UF | E7: 0.078368404 | F7: 1 | G7: 0.9195 | H7: 0.89645 | I7: 0.89645 | J7: 11511.065 | K7: 29755.273 | L7: 69572.01 | M7: 5546.0558 | N7: 119629.09 | O7: -0.24062234 | P7: -0.36194799 | Q7: UF
B8: Nexum | C8: Prospectivo | D8: USD | E8: 0.045786923 | F8: 1 | G8: 0.713 | H8: 0.4653 | I8: 0.4653 | J8: 324301.03 | K8: 617754.27 | L8: 1148464.7 | M8: 0 | N8: 414317.88 | O8: -0.30455109 | P8: -0.46649885 | Q8: USD reales
B9: Nexum | C9: Prospectivo | D9: UF | E9: 0.045786923 | F9: 0.999 | G9: 0.6451 | H9: 0.4534 | I9: 0.4534 | J9: 4786.9798 | K9: 13913.696 | L9: 34053.498 | M9: 0 | N9: 9146.1088 | O9: -0.30455109 | P9: -0.46649885 | Q9: UF
B10: AGF 85/15 | C10: Histórico 2013-2026 | D10: USD | E10: 0.10003514 | F10: 1 | G10: 0.99285 | H10: 0.9881 | I10: 0.9881 | J10: 985598.08 | K10: 2128040.1 | L10: 4548107.2 | M10: 4327838.1 | N10: 17614178 | O10: -0.28654946 | P10: -0.42291719 | Q10: USD reales
B11: AGF 85/15 | C11: Histórico 2013-2026 | D11: UF | E11: 0.10003514 | F11: 0.99995 | G11: 0.9695 | H11: 0.96355 | I11: 0.96355 | J11: 17134.395 | K11: 44864.004 | L11: 110168.85 | M11: 51794.513 | N11: 338927.8 | O11: -0.28654946 | P11: -0.42291719 | Q11: UF
B12: AGF 85/15 | C12: Prospectivo | D12: USD | E12: 0.043773079 | F12: 1 | G12: 0.6358 | H12: 0.4241 | I12: 0.4241 | J12: 257809.54 | K12: 585445.84 | L12: 1276154.8 | M12: 0 | N12: 290421.97 | O12: -0.39765385 | P12: -0.59753697 | Q12: USD reales
B13: AGF 85/15 | C13: Prospectivo | D13: UF | E13: 0.043773079 | F13: 0.9964 | G13: 0.5722 | H13: 0.3836 | I13: 0.3836 | J13: 3870.1353 | K13: 12262.797 | L13: 32293.044 | M13: 0 | N13: 3866.5475 | O13: -0.39765385 | P13: -0.59753697 | Q13: UF
B16: Palancas acordables con el cliente (escenario prospectivo, USD)
B17: Palanca (prospectivo, USD) | C17: P(Educación) | D17: P(Villarrica) | E17: P(Herencia) | F17: P(3 objetivos)
B18: Base | C18: 1 | D18: 0.713 | E18: 0.4653 | F18: 0.4653
B19: Herencia USD 250 mil | C19: 1 | D19: 0.713 | E19: 0.5762 | F19: 0.5762
B20: Villarrica -25% | C20: 1 | D20: 0.8698 | E20: 0.6211 | F20: 0.6211
B21: Ambas | C21: 1 | D21: 0.8698 | E21: 0.7483 | F21: 0.7483
B24: Capital humano: desempleo de Tomás (los aportes se cortan mientras está desempleado)
B25: Escenario de empleo | C25: Mercado | D25: P(Educación) | E25: P(Villarrica) | F25: P(Herencia) | G25: P(3 objetivos)
B26: Sin desempleo (base) | C26: Histórico | D26: 1 | E26: 0.98135 | F26: 0.95955 | G26: 0.95955
B27: Sin desempleo (base) | C27: Prospectivo | D27: 1 | E27: 0.713 | F27: 0.4653 | G27: 0.4653
B28: 5% anual, independiente del mercado; reempleo en ~2 años | C28: Histórico | D28: 1 | E28: 0.97435 | F28: 0.9475 | G28: 0.9475
B29: 5% anual, independiente del mercado; reempleo en ~2 años | C29: Prospectivo | D29: 1 | E29: 0.66815 | F29: 0.4235 | G29: 0.4235
B30: 5% normal y 25% si la cartera cayó >10% en 12 meses; reempleo ~2 años | C30: Histórico | D30: 1 | E30: 0.9713 | F30: 0.94385 | G30: 0.94385
B31: 5% normal y 25% si la cartera cayó >10% en 12 meses; reempleo ~2 años | C31: Prospectivo | D31: 0.99995 | E31: 0.6542 | F31: 0.4141 | G31: 0.4141
B32: 10% normal y 40% si la cartera cayó >10%; reempleo ~2 años | C32: Histórico | D32: 1 | E32: 0.96435 | F32: 0.9303 | G32: 0.9303
B33: 10% normal y 40% si la cartera cayó >10%; reempleo ~2 años | C33: Prospectivo | D33: 0.9999 | E33: 0.61055 | F33: 0.37695 | G33: 0.37695
B34: Estrés: 6% anual y pérdida PERMANENTE (sin reempleo) | C34: Histórico | D34: 0.99985 | E34: 0.91245 | F34: 0.8655 | G34: 0.8655
B35: Estrés: 6% anual y pérdida PERMANENTE (sin reempleo) | C35: Prospectivo | D35: 0.9957 | E35: 0.5003 | F35: 0.3024 | G35: 0.3024
B38: Abanico del patrimonio real (USD de hoy) — percentiles al cierre de cada año
B39: Histórico | J39: Prospectivo
B40: Año | C40: P10 | D40: P25 | E40: P50 | F40: P75 | G40: P90 | J40: Año | K40: P10 | L40: P25 | M40: P50 | N40: P75 | O40: P90
B41: 0 | C41: 144000 | D41: 144000 | E41: 144000 | F41: 144000 | G41: 144000 | J41: 0 | K41: 144000 | L41: 144000 | M41: 144000 | N41: 144000 | O41: 144000
B42: 1 | C42: 136454.11 | D42: 145546.72 | E42: 155716.38 | F42: 166313.62 | G42: 176050.47 | J42: 1 | K42: 132358.12 | L42: 141172.33 | M42: 151010.86 | N42: 161267.1 | O42: 170682.92
B43: 2 | C43: 149671.61 | D43: 162679.51 | E43: 178615.36 | F43: 195244.7 | G43: 211621.67 | J43: 2 | K43: 141174.84 | L43: 153419.93 | M43: 168400.31 | N43: 184028.12 | O43: 199439.4
B44: 3 | C44: 165345.96 | D44: 182118.44 | E44: 203316.67 | F44: 226051.6 | G44: 248357.99 | J44: 3 | K44: 151892.08 | L44: 167218.08 | M44: 186587.89 | N44: 207352.44 | O44: 227758.4
B45: 4 | C45: 182419.22 | D45: 203529.11 | E45: 229941.2 | F45: 258860.79 | G45: 288271.51 | J45: 4 | K45: 163351.47 | L45: 182170.08 | M45: 205625.55 | N45: 231214.49 | O45: 257322.16
B46: 5 | C46: 199689.56 | D46: 225812.48 | E46: 258541.4 | F46: 295487.03 | G46: 332315.74 | J46: 5 | K46: 174596.69 | L46: 197110.79 | M46: 225379.44 | N46: 257295.26 | O46: 288881.52
B47: 6 | C47: 219410.28 | D47: 249979.73 | E47: 289547.17 | F47: 333678.99 | G47: 379620.58 | J47: 6 | K47: 187317.98 | L47: 212969.2 | M47: 246144.16 | N47: 283212.54 | O47: 321686.16
B48: 7 | C48: 240419.18 | D48: 276066.66 | E48: 322860.3 | F48: 376379.53 | G48: 432771.82 | J48: 7 | K48: 200472.08 | L48: 229624.79 | M48: 267949.33 | N48: 311586.42 | O48: 357578.15
...

Sheet 09_Validacion
B2: Validación: correcciones, robustez y prueba fuera de muestra
B5: Impacto de las correcciones sobre el modelo original
B6: Versión | C6: Meses | D6: CAGR Momentum | E6: CAGR Low-Vol | F6: CAGR Commodities | G6: Cartera (pesos aprobados) CAGR | H6: Cartera Sharpe | I6: Cartera máx. caída | J6: BL SPY | K6: BL TLH | L6: BL VCLT | M6: BL MOM_CMD | N6: BL MOM_EQ | O6: BL LOW_VOL
B7: Modelo original (162 meses, vol. 1 mes) | C7: 162 | D7: 0.16524061 | E7: 0.11002153 | F7: 0.084596726 | G7: 0.10230295 | H7: 0.8762894 | I7: -0.20401697 | J7: 0.37889243 | K7: 0.16874764 | L7: 0.14602771 | M7: 0.061148179 | N7: 0.070596108 | O7: 0.17458793
B8: + incluye jul y dic 2018 (dato faltante corregido) | C8: 164 | D8: 0.15617751 | E8: 0.10716073 | F8: 0.07945914 | G8: 0.099495538 | H8: 0.84711621 | I8: -0.20401697 | J8: 0.37253156 | K8: 0.17067694 | L8: 0.14824283 | M8: 0.064850585 | N8: 0.071083129 | O8: 0.17261496
B9: + filtro de Sharpe con vol. 12 meses (versión vigente) | C9: 164 | D9: 0.16184388 | E9: 0.10716073 | F9: 0.07945914 | G9: 0.099933609 | H9: 0.84976461 | I9: -0.2047528 | J9: 0.37268829 | K9: 0.17089026 | L9: 0.14842799 | M9: 0.065944585 | N9: 0.070231253 | O9: 0.17181762
B10: Sensibilidad: costos en ambos lados | C10: 164 | D10: 0.15582621 | E10: 0.10472327 | F10: 0.076596543 | G10: 0.098927483 | H10: 0.84051845 | I10: -0.20535452 | J10: 0.37267494 | K10: 0.17088088 | L10: 0.1484199 | M10: 0.065826927 | N10: 0.070249752 | O10: 0.17194759
B12: Robustez de parámetros (un cambio a la vez; backtest completo)
B13: Estrategia | C13: Variante | D13: CAGR | E13: Volatilidad | F13: Sharpe | G13: Máx. caída | H13: Sharpe 2013-2019 | I13: Sharpe 2020-2026
B14: Momentum | C14: BASE (vigente) | D14: 0.16184388 | E14: 0.23760947 | F14: 0.68444486 | G14: -0.37424195 | H14: 0.84235562 | I14: 0.62402395
B15: Momentum | C15: Sin filtros absolutos (solo ranking) | D15: 0.17084229 | E15: 0.24233791 | F15: 0.70700549 | G15: -0.37306177 | H15: 0.82763522 | I15: 0.66337215
B16: Momentum | C16: Umbrales x2 (r6>10%, r12>20%) | D16: 0.17660381 | E16: 0.23671785 | F16: 0.73898264 | G16: -0.36206517 | H16: 0.88762331 | I16: 0.68473107
B17: Momentum | C17: Sin filtro de Sharpe | D17: 0.1650139 | E17: 0.24082576 | F17: 0.68955856 | G17: -0.36785463 | H17: 0.85693861 | I17: 0.62552345
B18: Momentum | C18: Top 15 | D18: 0.13501809 | E18: 0.20101738 | F18: 0.6521798 | G18: -0.35494245 | H18: 1.0108956 | I18: 0.44850253
B19: Momentum | C19: Top 20 | D19: 0.12811353 | E19: 0.18568535 | F19: 0.65697236 | G19: -0.30349191 | H19: 0.99952348 | I19: 0.4360532
B20: Momentum | C20: Límite sectorial 30% | D20: 0.16629562 | E20: 0.23507237 | F20: 0.70704069 | G20: -0.35671756 | H20: 0.93153906 | I20: 0.60187982
B21: Momentum | C21: Sin límite sectorial | D21: 0.18608358 | E21: 0.25110629 | F21: 0.74189633 | G21: -0.33952912 | H21: 0.86711619 | I21: 0.70807934
B22: Low-Volatility | C22: BASE (vigente) | D22: 0.10716073 | E22: 0.11960375 | F22: 0.77798309 | G22: -0.17847822 | H22: 1.269598 | I22: 0.41495096
B23: Low-Volatility | C23: Top 15 | D23: 0.10498518 | E23: 0.11912927 | F23: 0.76408717 | G23: -0.19176842 | H23: 1.3300035 | I23: 0.3736198
B24: Low-Volatility | C24: Top 20 | D24: 0.10992134 | E24: 0.12050259 | F24: 0.79433885 | G24: -0.22186697 | H24: 1.4420026 | I24: 0.36819676
B25: Low-Volatility | C25: Límite sectorial 30% | D25: 0.1065488 | E25: 0.11954527 | F25: 0.77360641 | G25: -0.18831551 | H25: 1.3673337 | I25: 0.34795513
... B31: Commodities | C31: Sin límite de volatilidad | D31: 0.080896159 | E31: 0.168958 | F31: 0.44885675 | G31: -0.30131418 | H31: 0.29838392 | I31: 0.56658694
B33: Walk-forward: calibrar con 2013-2019, evaluar 2020-2026
B34: Cartera | C34: Período | D34: CAGR | E34: Volatilidad | F34: Sharpe | G34: Máx. caída | H34: w SPY | I34: w TLH | J34: w VCLT | K34: w MOM_CMD | L34: w MOM_EQ | M34: w LOW_VOL
B35: Markowitz optimizado con 2013-2019 | C35: Dentro de muestra 2013-2019 | D35: 0.1056684 | E35: 0.066351761 | F35: 1.4614306 | G35: -0.046013745 | H35: 0.35843583 | I35: 0.26156417 | J35: 0.08 | K35: 0.018997264 | L35: 9.420599e-18 | M35: 0.28100274
B36: Markowitz optimizado con 2013-2019 | C36: Fuera de muestra 2020-2026 | D36: 0.07451328 | E36: 0.11504943 | F36: 0.44872794 | G36: -0.20542132 | H36: 0.35843583 | I36: 0.26156417 | J36: 0.08 | K36: 0.018997264 | L36: 9.420599e-18 | M36: 0.28100274
B37: Black-Litterman calibrado con 2013-2019 | C37: Dentro de muestra 2013-2019 | D37: 0.12016057 | E37: 0.080784736 | F37: 1.3760573 | G37: -0.093163449 | H37: 0.48667854 | I37: 0.066946145 | J37: 0.14637531 | K37: 0.052610263 | L37: 0.075007855 | M37: 0.17238188
B38: Black-Litterman calibrado con 2013-2019 | C38: Fuera de muestra 2020-2026 | D38: 0.11073057 | E38: 0.13429235 | F38: 0.65084712 | G38: -0.20490278 | H38: 0.48667854 | I38: 0.066946145 | J38: 0.14637531 | K38: 0.052610263 | L38: 0.075007855 | M38: 0.17238188
B39: Pesos aprobados (BL del modelo) | C39: Dentro de muestra 2013-2019 | D39: 0.10761655 | E39: 0.070639546 | F39: 1.4020459 | G39: -0.075759872 | H39: 0.3789 | I39: 0.1687 | J39: 0.146 | K39: 0.0611 | L39: 0.0706 | M39: 0.1746
B40: Pesos aprobados (BL del modelo) | C40: Fuera de muestra 2020-2026 | D40: 0.09192387 | E40: 0.12259329 | F40: 0.56034579 | G40: -0.2047528 | H40: 0.3789 | I40: 0.1687 | J40: 0.146 | K40: 0.0611 | L40: 0.0706 | M40: 0.1746
B41: Pesos iguales (1/6) | C41: Dentro de muestra 2013-2019 | D41: 0.095147502 | E41: 0.070866574 | F41: 1.2367992 | G41: -0.086652537 | H41: 0.16666667 | I41: 0.16666667 | J41: 0.16666667 | K41: 0.16666667 | L41: 0.16666667 | M41: 0.16666667
B42: Pesos iguales (1/6) | C42: Fuera de muestra 2020-2026 | D42: 0.093137149 | E42: 0.11908661 | F42: 0.58255565 | G42: -0.17335662 | H42: 0.16666667 | I42: 0.16666667 | J42: 0.16666667 | K42: 0.16666667 | L42: 0.16666667 | M42: 0.16666667
B44: Sensibilidad al universo de commodities (control del sesgo de selección)
B45: Universo | C45: Cartera CAGR | D45: Cartera Sharpe | E45: Cartera máx. caída | F45: P(3 objetivos) histórico | G45: Peso BL recalibrado commodities
B46: 5 ETF (vigente: GLD, USO, DBA, SLV, CPER) | C46: 0.099933609 | D46: 0.84976461 | E46: -0.2047528 | F46: 0.95955 | G46: 0.065944585
B47: 3 ETF (original: GLD, USO, DBA) | C47: 0.097369403 | D47: 0.83369296 | E47: -0.20423033 | F47: 0.9477 | G47: 0.10148483
B49: Sesgos y limitaciones declarados
B50: • Supervivencia: controlado con membresía histórica del S&P 500 (point-in-time).
B51: • Anticipación: señal al cierre de t, retorno desde t+1. Limitación: clasificación GICS actual (no histórica) en el límite sectorial; afecta sobre todo antes de 2016 y a ~3% de posiciones sin clasificar.
B52: • Datos faltantes: un precio faltante en el mes se trata como 0% en esa posición (antes eliminaba el mes completo en Low-Vol).
...

Sheet 10_Bitacora_Auditoria
B2: Bitácora de auditoría del modelo original (Modelo_Nexum_Final.xlsx)
B5: Gravedad | C5: Hallazgo | D5: Corrección en v2
B6: Alta | C6: Fórmulas sin valores guardados (archivo escrito por código, nunca recalculado) | D6: Este archivo se recalcula y guarda en Excel antes de entregarse
B7: Alta | C7: Mezcla de dos arquitecturas: hojas y textos del diseño anterior con calce LDI de Educación (03, 05, partes de 02, 04, 09) | D7: Se eliminan; el modelo describe solo la cartera única
B8: Alta | C8: Referencias a 'BAB_EQ' (Betting Against Beta) en 05_Datos_Historicos | D8: Eliminadas; la estrategia se denomina Low-Volatility
B9: Alta | C9: Low-Vol devolvía NaN en jul-2018 y dic-2018; el modelo eliminó esos meses de las 6 series (162 en vez de 164 meses) | D9: Dato faltante = 0% en esa posición; ventana completa de 164 meses
B10: Alta | C10: Filtro 'Sharpe 12m' de Momentum calculado con volatilidad de 1 mes en el backtest, pero con 12 meses en la operación (Senales_Hoy.py) | D10: Backtest con volatilidad de 12 meses (regla documentada = regla operada)
B11: Media | C11: Black-Litterman: columna π de la sección 5 desplazada una fila (=D32 en vez de =D31) | D11: π y μ_BL se calculan con fórmulas matriciales vivas
B12: Media | C12: μ_BL y pesos pegados como valores, no auditables en el Excel | D12: μ_BL con MMULT/MINVERSE; pesos de SLSQP marcados como resultado de Python
B13: Media | C13: Benchmarks inconsistentes entre hojas 04 y 08 (BCOM, S&P Low Vol, S&P Momentum vs mezcla, SPY, QMOM) | D13: Un solo benchmark por sleeve, invertible y del mismo universo (hoja 07)
